<?xml version="1.0" encoding="utf-8"?>
<!-- This URDF was automatically created by SolidWorks to URDF Exporter! Originally created by Stephen Brawner (brawner@gmail.com) 
     Commit Version: 1.6.0-4-g7f85cfe  Build Version: 1.6.7995.38578
     For more information, please see http://wiki.ros.org/sw_urdf_exporter -->
<robot
  name="brc_arm_description">
  <link
    name="base_link">
    <inertial>
      <origin
        xyz="-0.2365 -0.11407 0.091275"
        rpy="0 0 0" />
      <mass
        value="127.99" />
      <inertia
        ixx="11.646"
        ixy="0.74605"
        ixz="0.11702"
        iyy="17.633"
        iyz="0.24149"
        izz="13.254" />
    </inertial>
    <visual>
      <origin
        xyz="0 0 0"
        rpy="0 0 0" />
      <geometry>
        <mesh
          filename="package://brc_arm_description/meshes/base_link.STL" />
      </geometry>
      <material
        name="">
        <color
          rgba="0.79216 0.81961 0.93333 1" />
      </material>
    </visual>
    <collision>
      <origin
        xyz="0 0 0"
        rpy="0 0 0" />
      <geometry>
        <mesh
          filename="package://brc_arm_description/meshes/base_link.STL" />
      </geometry>
    </collision>
  </link>
  <link
    name="carriage_link">
    <inertial>
      <origin
        xyz="2.5422E-18 0.025 0.053905"
        rpy="0 0 0" />
      <mass
        value="0.44772" />
      <inertia
        ixx="0.001099"
        ixy="8.147E-21"
        ixz="1.4734E-20"
        iyy="0.0011932"
        iyz="-4.9973E-22"
        izz="0.00028077" />
    </inertial>
    <visual>
      <origin
        xyz="0 0 0"
        rpy="0 0 0" />
      <geometry>
        <mesh
          filename="package://brc_arm_description/meshes/carriage_link.STL" />
      </geometry>
      <material
        name="">
        <color
          rgba="0.79216 0.81961 0.93333 1" />
      </material>
    </visual>
    <collision>
      <origin
        xyz="0 0 0"
        rpy="0 0 0" />
      <geometry>
        <mesh
          filename="package://brc_arm_description/meshes/carriage_link.STL" />
      </geometry>
    </collision>
  </link>
  <joint
    name="carriage_joint"
    type="prismatic">
    <origin
      xyz="0 0 0.065"
      rpy="1.5708 0 0" />
    <parent
      link="base_link" />
    <child
      link="carriage_link" />
    <axis
      xyz="0 1 0" />
    <limit
      lower="0"
      upper="0.885"
      effort="0"
      velocity="0" />
  </joint>
  <link
    name="midarm1_link">
    <inertial>
      <origin
        xyz="-0.20356 0.024067 -0.023364"
        rpy="0 0 0" />
      <mass
        value="0.8362" />
      <inertia
        ixx="0.0015195"
        ixy="-0.00010292"
        ixz="0.00024052"
        iyy="0.007027"
        iyz="-9.3176E-05"
        izz="0.0071837" />
    </inertial>
    <visual>
      <origin
        xyz="0 0 0"
        rpy="0 0 0" />
      <geometry>
        <mesh
          filename="package://brc_arm_description/meshes/midarm1_link.STL" />
      </geometry>
      <material
        name="">
        <color
          rgba="0.79216 0.81961 0.93333 1" />
      </material>
    </visual>
    <collision>
      <origin
        xyz="0 0 0"
        rpy="0 0 0" />
      <geometry>
        <mesh
          filename="package://brc_arm_description/meshes/midarm1_link.STL" />
      </geometry>
    </collision>
  </link>
  <joint
    name="midarm1_joint"
    type="revolute">
    <origin
      xyz="0 0 0.1"
      rpy="0 0.5236 0" />
    <parent
      link="carriage_link" />
    <child
      link="midarm1_link" />
    <axis
      xyz="0 1 0" />
    <limit
      lower="0"
      upper="2.7423"
      effort="0"
      velocity="0" />
  </joint>
  <link
    name="midarm2_link">
    <inertial>
      <origin
        xyz="0.0437798591057959 0.0206817493001328 2.4980018054066E-16"
        rpy="0 0 0" />
      <mass
        value="0.0646775902886998" />
      <inertia
        ixx="2.3728145359128E-05"
        ixy="-1.49350689133807E-06"
        ixz="1.33407689192552E-19"
        iyy="7.7948360762991E-05"
        iyz="1.18849310411619E-20"
        izz="9.1312862306253E-05" />
    </inertial>
    <visual>
      <origin
        xyz="0 0 0"
        rpy="0 0 0" />
      <geometry>
        <mesh
          filename="package://brc_arm_description/meshes/midarm2_link.STL" />
      </geometry>
      <material
        name="">
        <color
          rgba="0.792156862745098 0.819607843137255 0.933333333333333 1" />
      </material>
    </visual>
    <collision>
      <origin
        xyz="0 0 0"
        rpy="0 0 0" />
      <geometry>
        <mesh
          filename="package://brc_arm_description/meshes/midarm2_link.STL" />
      </geometry>
    </collision>
  </link>
  <joint
    name="midarm2_joint"
    type="revolute">
    <origin
      xyz="-0.35 0 0"
      rpy="0 -0.43633 0" />
    <parent
      link="midarm1_link" />
    <child
      link="midarm2_link" />
    <axis
      xyz="0 1 0" />
    <limit
      lower="-4.7124"
      upper="0"
      effort="0"
      velocity="0" />
  </joint>
  <link
    name="wrist1_link">
    <inertial>
      <origin
        xyz="0.0903131624724207 -0.00462740982819057 0.0208801756228061"
        rpy="0 0 0" />
      <mass
        value="0.419666572951629" />
      <inertia
        ixx="0.000346854880152641"
        ixy="2.70709984964626E-06"
        ixz="-5.02615984609935E-05"
        iyy="0.00143713508844135"
        iyz="3.62665449634077E-05"
        izz="0.00143304792270374" />
    </inertial>
    <visual>
      <origin
        xyz="0 0 0"
        rpy="0 0 0" />
      <geometry>
        <mesh
          filename="package://brc_arm_description/meshes/wrist1_link.STL" />
      </geometry>
      <material
        name="">
        <color
          rgba="0.792156862745098 0.819607843137255 0.933333333333333 1" />
      </material>
    </visual>
    <collision>
      <origin
        xyz="0 0 0"
        rpy="0 0 0" />
      <geometry>
        <mesh
          filename="package://brc_arm_description/meshes/wrist1_link.STL" />
      </geometry>
    </collision>
  </link>
  <joint
    name="wrist1_joint"
    type="revolute">
    <origin
      xyz="0.08 0.025 0"
      rpy="0 0 0" />
    <parent
      link="midarm2_link" />
    <child
      link="wrist1_link" />
    <axis
      xyz="0 0 1" />
    <limit
      lower="-1.57"
      upper="0"
      effort="0"
      velocity="0" />
  </joint>
  <link
    name="wrist2_link">
    <inertial>
      <origin
        xyz="0.043767510273945 0.018260701276372 0.0065358362738916"
        rpy="0 0 0" />
      <mass
        value="0.129512939632169" />
      <inertia
        ixx="0.000129578871276748"
        ixy="2.78573307339072E-06"
        ixz="-2.66314903931951E-06"
        iyy="8.51895227169166E-05"
        iyz="-9.11411436035313E-07"
        izz="0.000185624075448265" />
    </inertial>
    <visual>
      <origin
        xyz="0 0 0"
        rpy="0 0 0" />
      <geometry>
        <mesh
          filename="package://brc_arm_description/meshes/wrist2_link.STL" />
      </geometry>
      <material
        name="">
        <color
          rgba="0.792156862745098 0.819607843137255 0.933333333333333 1" />
      </material>
    </visual>
    <collision>
      <origin
        xyz="0 0 0"
        rpy="0 0 0" />
      <geometry>
        <mesh
          filename="package://brc_arm_description/meshes/wrist2_link.STL" />
      </geometry>
    </collision>
  </link>
  <joint
    name="wrist2_joint"
    type="revolute">
    <origin
      xyz="0.225 0 0"
      rpy="-3.1416 -1.2217 3.1416" />
    <parent
      link="wrist1_link" />
    <child
      link="wrist2_link" />
    <axis
      xyz="0 1 0" />
    <limit
      lower="0"
      upper="4.165"
      effort="0"
      velocity="0" />
  </joint>
  <link
    name="EEbase_link">
    <inertial>
      <origin
        xyz="2.4980018054066E-16 -2.51187959321442E-15 -0.0327794628998193"
        rpy="0 0 0" />
      <mass
        value="0.0926044760959502" />
      <inertia
        ixx="4.81318826783348E-05"
        ixy="-1.57510711271281E-20"
        ixz="2.37169225231204E-20"
        iyy="7.32482359165231E-05"
        iyz="-9.81194031396023E-20"
        izz="3.29932559448168E-05" />
    </inertial>
    <visual>
      <origin
        xyz="0 0 0"
        rpy="0 0 0" />
      <geometry>
        <mesh
          filename="package://brc_arm_description/meshes/EEbase_link.STL" />
      </geometry>
      <material
        name="">
        <color
          rgba="0.792156862745098 0.819607843137255 0.933333333333333 1" />
      </material>
    </visual>
    <collision>
      <origin
        xyz="0 0 0"
        rpy="0 0 0" />
      <geometry>
        <mesh
          filename="package://brc_arm_description/meshes/EEbase_link.STL" />
      </geometry>
    </collision>
  </link>
  <joint
    name="EEbase_joint"
    type="continuous">
    <origin
      xyz="0.10009 0 0"
      rpy="0 -1.5708 0" />
    <parent
      link="wrist2_link" />
    <child
      link="EEbase_link" />
    <axis
      xyz="0 0 1" />
  </joint>
  <link
    name="Rlink_link">
    <inertial>
      <origin
        xyz="0.0399999999999999 -0.00249999999999992 1.66533453693773E-16"
        rpy="0 0 0" />
      <mass
        value="0.00668722339297277" />
      <inertia
        ixx="1.38550163626323E-07"
        ixy="-1.87727288905576E-21"
        ixz="-8.27511484798049E-21"
        iyy="4.66129432520503E-06"
        iyz="-1.14346024494546E-22"
        izz="4.55060759238276E-06" />
    </inertial>
    <visual>
      <origin
        xyz="0 0 0"
        rpy="0 0 0" />
      <geometry>
        <mesh
          filename="package://brc_arm_description/meshes/Rlink_link.STL" />
      </geometry>
      <material
        name="">
        <color
          rgba="0.792156862745098 0.819607843137255 0.933333333333333 1" />
      </material>
    </visual>
    <collision>
      <origin
        xyz="0 0 0"
        rpy="0 0 0" />
      <geometry>
        <mesh
          filename="package://brc_arm_description/meshes/Rlink_link.STL" />
      </geometry>
    </collision>
  </link>
  <joint
    name="Rlink_joint"
    type="revolute">
    <origin
      xyz="0.024 -0.011 -0.014095"
      rpy="0 0 0" />
    <parent
      link="EEbase_link" />
    <child
      link="Rlink_link" />
    <axis
      xyz="0 1 0" />
    <limit
      lower="-1.67"
      upper="0"
      effort="0"
      velocity="0" />
  </joint>
  <link
    name="Rfinger_link">
    <inertial>
      <origin
        xyz="0.0174831476155695 0.0707338411471633 -0.011"
        rpy="0 0 0" />
      <mass
        value="0.052748844949343" />
      <inertia
        ixx="9.60936833531591E-05"
        ixy="-3.36352218446777E-05"
        ixz="3.61872312377867E-20"
        iyy="1.68927505422671E-05"
        iyz="8.49388270800886E-20"
        izz="0.000108731360402846" />
    </inertial>
    <visual>
      <origin
        xyz="0 0 0"
        rpy="0 0 0" />
      <geometry>
        <mesh
          filename="package://brc_arm_description/meshes/Rfinger_link.STL" />
      </geometry>
      <material
        name="">
        <color
          rgba="1 0.717647058823529 0.819607843137255 1" />
      </material>
    </visual>
    <collision>
      <origin
        xyz="0 0 0"
        rpy="0 0 0" />
      <geometry>
        <mesh
          filename="package://brc_arm_description/meshes/Rfinger_link.STL" />
      </geometry>
    </collision>
  </link>
  <joint
    name="Rfinger_joint"
    type="continuous">
    <origin
      xyz="0 0 0"
      rpy="-1.5708 0 -3.1416" />
    <parent
      link="Rlink_link" />
    <child
      link="Rfinger_link" />
    <axis
      xyz="0 0 1" />
    <mimic
      joint="Rlink_joint"
      multiplier="1"
      offset="0" />
  </joint>
  <link
    name="Llink_link">
    <inertial>
      <origin
        xyz="-0.0400000000000001 -0.00249999999999997 -2.22044604925031E-16"
        rpy="0 0 0" />
      <mass
        value="0.00668722339297277" />
      <inertia
        ixx="1.38550163626324E-07"
        ixy="-1.91820017504688E-21"
        ixz="-8.07990022341797E-21"
        iyy="4.66129432520503E-06"
        iyz="-2.15898008823243E-22"
        izz="4.55060759238276E-06" />
    </inertial>
    <visual>
      <origin
        xyz="0 0 0"
        rpy="0 0 0" />
      <geometry>
        <mesh
          filename="package://brc_arm_description/meshes/Llink_link.STL" />
      </geometry>
      <material
        name="">
        <color
          rgba="0.792156862745098 0.819607843137255 0.933333333333333 1" />
      </material>
    </visual>
    <collision>
      <origin
        xyz="0 0 0"
        rpy="0 0 0" />
      <geometry>
        <mesh
          filename="package://brc_arm_description/meshes/Llink_link.STL" />
      </geometry>
    </collision>
  </link>
  <joint
    name="Llink_joint"
    type="continuous">
    <origin
      xyz="-0.024 -0.011 -0.014095"
      rpy="0 0 0" />
    <parent
      link="EEbase_link" />
    <child
      link="Llink_link" />
    <axis
      xyz="0 1 0" />
    <mimic
      joint="Rlink_joint"
      multiplier="1"
      offset="0" />
  </joint>
  <link
    name="Lfinger_link">
    <inertial>
      <origin
        xyz="0.017483 0.070734 0.011"
        rpy="0 0 0" />
      <mass
        value="0.052749" />
      <inertia
        ixx="9.6094E-05"
        ixy="-3.3635E-05"
        ixz="1.0851E-20"
        iyy="1.6893E-05"
        iyz="2.7634E-20"
        izz="0.00010873" />
    </inertial>
    <visual>
      <origin
        xyz="0 0 0"
        rpy="0 0 0" />
      <geometry>
        <mesh
          filename="package://brc_arm_description/meshes/Lfinger_link.STL" />
      </geometry>
      <material
        name="">
        <color
          rgba="1 0.71765 0.81961 1" />
      </material>
    </visual>
    <collision>
      <origin
        xyz="0 0 0"
        rpy="0 0 0" />
      <geometry>
        <mesh
          filename="package://brc_arm_description/meshes/Lfinger_link.STL" />
      </geometry>
    </collision>
  </link>
  <joint
    name="Lfinger_joint"
    type="continuous">
    <origin
      xyz="-0.08 0 0"
      rpy="-1.5708 0 0" />
    <parent
      link="Llink_link" />
    <child
      link="Lfinger_link" />
    <axis
      xyz="0 0 1" />
    <mimic
      joint="Llink_joint"
      multiplier="1"
      offset="0" />
  </joint>
</robot>